Workbook

Sheet Data
B2: TERA / TERA ULANG | U2: PEMERINTAH KOTA SINGKAWANG | BC2: CERAPAN Crp.PU-01.2026
U3: DINAS PERDAGANGAN, PERINDUSTRIAN, KOPERASI DAN USAHA KECIL MENENGAH
B5: POMPA UKUR BBM | U5: UPT METROLOGI LEGAL | BC5: Pemeriksaan Visual dan Fasilitas
U6: Jalan Firdaus H. Rais Nomor 38 - Singkawang 79123
B7: NOMOR ORDER | L7: PENGUJIAN DILAKUKAN DALAM RANGKA | BC7: - | BF7: TERA
B8: xxxxxxxxx | BC8: =+IF(BC7="-","x","-") -> x | BF8: TERA ULANG
B9: DATA PENGUJIAN
C10: Nama Pemilik | O10: : | Q10: PT. RATU SEPUDAK JAYA | AX10: PETUGAS
C11: Nomor SPBU | O11: : | Q11: 79123019
C12: Nama Contact Person | O12: : | Q12: Achoy
C13: Alamat Terpasang | O13: : | Q13: Jl. Ratus Sepudak Kel. Sungai Wi Kec. Singkawag Tenah | AX13: 1.
C14: Nomor Pompa Ukur | O14: : | Q14: P1-3
C15: TanggalPengujian | O15: : | Q15: 24 Mei 2026 | AX15: 2.
B17: IDENTITAS UTTP | AG17: KONDISI OPERASI
C18: Merek | O18: : | Q18: TATSUNO | AH18: Laju Alir Maksimum | AT18: : | AU18: 65 | AY18: L/min
C19: Tipe | O19: : | Q19: ADAT SDA 2222 P | AH19: Laju Alir Minimum | AT19: : | AU19: 6.5 | AY19: L/min | BH19: x
C20: Nomor Seri | O20: : | Q20: AA12345667 | AH20: MMQ (jika ada) | AT20: : | AU20: 0 | AY20: Liter | BH20: x
C21: Jumlah nozzle | O21: : | Q21: AA12345668 | AH21: Nomor Persetujuan Tipe | AT21: :
C22: Tahun Pembuatan | O22: : | Q22: 24 Januari 2021
B23: PEMERIKSAAN
B24: No. | E24: Dekripsi | AU24: Ya | AY24: Tidak | BC24: Keterangan
B25: 1 | E25: Apakah PU BBM dilengkapi dengan Persetujuan Tipe (untuk Tera)? - Apakah informasi pada pelat identitas sesuai dengan Persetujuan Tipe - Apakah spesifikasi teknis PU BBM sesuai dengan Persetujuan Tipe? | AU25: x | AY25: =+IF(AU25="x","-","x") -> -
B28: 2 | E28: Apakah PU BBM sudah digunakan dengan benar ? - Apakah tanda tera sebelumnya masih utuh dan tidak ada yang rusak? - Apakah tidak terdapat alat tambahan yang merubah spesifikasi dan/atau mempengaruhi hasil pengukuran PU BBM? | AU28: x | AY28: =+IF(AU28="x","-","x") -> -
B33: 3 | E33: Apakah semua deskripsi yang wajib jelas terpasang pada pelat identitas ada dan terpasang tetap pada PU BBM? - Apakah identitas pada pelat data lengkap sesuai syarat teknis? - Apakah identitas pada pelat data mudah terlihat, jelas dan mudah dibaca? | AU33: x | AY33: =IF(AU33="x","-","x") -> -
B37: 4 | E37: Apakah PU BBM dalam kondisi lengkap dan bersih? | AU37: x | AY37: =IF(AU37="x","-","x") -> -
B38: 5 | E38: Apakah PU BBM terpasang dengan kokoh pada pondasinya atau pada sasis Tangki Ukur Mobil BBM? | AU38: x | AY38: =IF(AU38="x","-","x") -> -
B40: 6 | E40: Apakah tidak terdapat kerusakan pada penutup Perangkat Penunjukan? | AU40: x | AY40: =IF(AU40="x","-","x") -> -
B41: 7 | E41: Apakah Gelas Penglihat bersih serta penuh dengan produk? | AU41: x | AY41: =IF(AU41="x","-","x") -> -
B42: 8 | E42: Apakah penunjukan volume, harga satuan, dan total harga sesuai dengan Slang yang dipilih? | AU42: x | AY42: =IF(AU42="x","-","x") -> -
B44: 9 | E44: Apakah semua penunjukan terlihat jelas pada saat siang dan malam hari? | AU44: x | AY44: =IF(AU44="x","-","x") -> -
B45: 10 | E45: Apakah Slang dalam kondisi baik, (pada slang apakah ditemukan konsdisi seperti lecet, retak, atau pembungkus Slangnya telah usang)? | AU45: x | AY45: =IF(AU45="x","-","x") -> -
B47: 11 | E47: Apakah masing-masing nozzle menghentikan aliran cairan ketika dikembalikan ke tempat penyimpanannya? | AU47: x | AY47: =IF(AU47="x","-","x") -> -
B49: 12 | E49: Apakah pada PU BBM tidak ditemukan adanya kebocoran atau rembesan cairan? | AU49: x | AY49: =IF(AU49="x","-","x") -> -
B50: HASIL PEMERIKSAAN
C52: HASIL | H52: : | J52: =IF(AND($BC$7="-",$BC$8="-"),"",IF(AND($BC$7="x",$AU$25="x",$AU$28="x",$AU$33="x",$AU$37="x",$AU$38="x",$AU$40="x",$AU$41="x",$AU$42="x",$AU$44="x",$AU$45="x",$AU$47="x",$AU$49="x"),"✓",IF(AND($BC$8="x",$AU$25="x",$AU$28="x",$AU$33="x",$AU$37="x",$AU$38="x",$AU$40="x",$AU$41="x",$AU$42="x",$AU$44="x",$AU$45="x",$AU$49="x"),"✓",""))) -> ✓ | O52: LANJUT KE PENGUJIAN | V52: =IF(AND($BC$7="-",$BC$8="-"),"",IF(AND($BC$7="x",OR($AY$25="x",$AY$28="x",$AY$33="x",$AY$37="x",$AY$38="x",$AY$40="x",$AY$41="x",$AY$42="x",$AY$44="x",$AY$45="x",$AY$47="x",$AY$49="x")),"✓",IF(AND($BC$8="x",OR($AY$28="x",$AY$33="x",$AY$37="x",$AY$38="x",$AY$40="x",$AY$41="x",$AY$42="x",$AY$44="x",$AY$45="x",$AY$47="x",$AY$49="x")),"✓",""))) | AA52: TIDAK DAPAT DIUJI | AH52: KETERANGAN | AP52: :
B54: CATATAN | H54: :
I55: Tidak terdapat perangkat yang terbagi, sehingga tidak terdapat fasilitas interlock
T61: =IF(AND(Data!BC7="-",Data!BC8="-"),"",IF(AND(CA37="BATAL",BL40="x",BL41="x",BL42="x",BL44="x",BL46="x",BL47="x",BL48="x",BL51="x",BL53="x",),"✓",""))

Sheet Cerapan
B2: TERA / TERA ULANG | T2: PEMERINTAH KOTA SINGKAWANG | BJ2: CERAPAN Crp.PU-01.2026
T3: DINAS PERDAGANGAN, PERINDUSTRIAN, KOPERASI DAN USAHA KECIL MENENGAH
B5: POMPA UKUR BBM | T5: UPT METROLOGI LEGAL | BJ5: Pengujian Unjuk Kerja
T6: Jalan Firdaus H. Rais Nomor 38 - Singkawang 79123
B7: NOMOR ORDER | L7: PENGUJIAN DILAKUKAN DALAM RANGKA | BJ7: - | BM7: TERA
BJ8: x | BM8: TERA ULANG
B9: DATA PENGUJIAN
C10: Nomor PU BBM | M10: : | N10: =Data!$Q$11 -> 79123019 | BE10: PETUGAS
C11: Nomor Seri PU BBM | M11: : | N11: =Data!$Q$18 -> TATSUNO
C12: Identifikasi Nozzle | M12: : | N12: =Data!$Q$14 -> P1-3
C13: Jenis Cairan | M13: : | N13: Pertamax Turbo | BE13: 1.
C14: Harga Satuan | M14: : | N14: Rp. | P14: 10000 | V14: / L
C15: Tanggal Pengujian | M15: : | N15: =Data!$Q$15 -> 24 Mei 2026 | BE15: 2.
B17: DATA BEJANA UKUR
C18: Merek | M18: : | N18: ANKATAMA | AP18: Volume Nominal ( VN ) | BE18: : | BF18: 20 | BP18: L | CG18: Solar
C19: Tipe | M19: : | N19: Basah | AP19: Volume Sebenarnya ( V28 ) | BE19: : | BF19: 19.9965 | BP19: L | CG19: Bio Solar
C20: Nomor Seri | M20: : | N20: ATM050618 | AP20: Skala Utama Sebenarnya | BE20: : | BF20: 10.3 | BP20: mL | CG20: Pertalie
AP21: Tanggal Verifikasi Terakhir | BE21: : | CG21: Pertamax
B22: HASIL PENGUJIAN | CG22: Pertamax Plus
B23: Pembacaan Totalisator | X23: Sebelum uji (a) : | AF23: 100 | AL23: L | AN23: Sesudah uji (b) : | AV23: 200 | BB23: L | BD23: Total terpakai (b-a) : | BN23: =IF(OR(ISBLANK(AF23),ISBLANK(AV23)),"",AV23-AF23) -> 100 | BR23: L | CG23: Pertamax Turbo
CG24: Dexlite
B25: Qmin dan Qmaks. Pada Plat Identitas | Y25: Q maks. = | AD25: =+IF(ISBLANK(Data!$AU$18),"",Data!$AU$18) -> 65 | AJ25: L/min | AO25: Q min. = | AS25: =+IF(ISBLANK(Data!$AU$19),"",Data!$AU$19) -> 6.5 | AY25: L/min | BD25: Rasio (Qmaks - Qmin) = | BN25: =IF(OR(ISBLANK(Data!$AU$18),ISBLANK(Data!$AU$19)),"",Cerapan!$AD$25/Cerapan!$AS$25) -> 10 | BR25: L | CG25: Pertamina Dex
B26: Akurasi | X26: Laju Alir Operasional | AN26: Laju Alir Maksimum | BD26: Laju Alir Minimum | CA26: (mL)
B27: VREF = V28 + Volume penunjukan skala BUS | X27: Preset Volume | AN27: Preset Harga | BD27: No Preset (jika bisa) | CA27: (skala)
B28: atau | X28: VFD | AB28: Nonius | AF28: VREF | AJ28: EFD | AN28: VFD | AR28: Nonius | AV28: VREF | AZ28: EFD | BD28: VFD | BH28: Nonius | BL28: VREF | BP28: EFD
B29: VREF = V28 + (pembacaan Jumlah Skala x Nilai Skala Utama sebenarnya) | CA29: volume/pulse
X30: ( L ) | AB30: (mL) | AF30: ( L ) | AJ30: ( % ) | AN30: ( L ) | AR30: (mL) | AV30: ( L ) | AZ30: ( % ) | BD30: ( L ) | BH30: (mL) | BL30: ( L ) | BP30: ( % ) | CA30: pulse/volume
B31: Penyerahan ke-1 | X31: 20 | AB31: -22 | AF31: =+IF(ISBLANK($AB$31),"",IF($AB$30="(skala)",$BF$19+($AB$31*$BF$20/1000),$BF$19+$AB$31/1000)) -> 19.9745 | AJ31: =+IF(ISBLANK($X$31),"",($X$31-$AF$31)/$X$31*100) -> 0.1275 | AN31: 20 | AR31: -35 | AV31: =+IF(ISBLANK($AB$31),"",IF($AB$30="(skala)",$BF$19+($AR$31*$BF$20/1000),$BF$19+$AR$31/1000)) -> 19.9615 | AZ31: =+IF(ISBLANK($AN$31),"",($AN$31-$AV$31)/$AN$31*100) -> 0.1925 | BD31: 20 | BH31: -55 | BL31: =+IF(ISBLANK($AB$31),"",IF($AB$30="(skala)",$BF$19+($BH$31*$BF$20/1000),$BF$19+$BH$31/1000)) -> 19.9415 | BP31: =+IF(ISBLANK($BD$31),"",($BD$31-$BL$31)/$BD$31*100) -> 0.2925
B32: Penyerahan ke-2 | X32: 20 | AB32: -19 | AF32: =+IF(ISBLANK($AB$31),"",IF($AB$30="(skala)",$BF$19+($AB$32*$BF$20/1000),$BF$19+$AB$32/1000)) -> 19.9775 | AJ32: =+IF(ISBLANK($X$32),"",($X$32-$AF$32)/$X$32*100) -> 0.1125 | CA32: tanpa hose reel
B33: Penyerahan ke-3 | X33: 20 | AB33: -22 | AF33: =+IF(ISBLANK($AB$31),"",IF($AB$30="(skala)",$BF$19+($AB$33*$BF$20/1000),$BF$19+$AB$33/1000)) -> 19.9745 | AJ33: =+IF(ISBLANK($X$33),"",($X$33-$AF$33)/$X$33*100) -> 0.1275 | CA33: dengan hose reel
B34: Kesalahan rata-rata (EAV = Σ E FD / 3) | X34: =IF(ISBLANK($X$33),"",AVERAGE($AJ$31:$AM$33)) -> 0.1225 | AJ34: % | AN34: =IF(ISBLANK($AN$31),"",AVERAGE($AZ$31:$BC$33)) -> 0.1925 | AZ34: % | BD34: =IF(ISBLANK($BD$31),"",AVERAGE($BP$31:$BS$33)) -> 0.2925 | BP34: %
B35: Kemampuan Ulang ( R = E FD maks. - E FD min. ) | X35: =+IF(ISBLANK($X$33),"",MAX($AJ$31:$AM$33)-MIN($AJ$31:$AM$33)) -> 0.015 | AJ35: % | CA35: (analog)
B36: Meter Faktor rata-rata (MF = Σ V REF / Σ V FD) | X36: Σ V REF = | AB36: =+IF(OR(ISBLANK($AB$33),ISBLANK($AR$31),ISBLANK($BH$31)),"",SUM($AF$31:$AI$33,$AV$31:$AY$33,$BL$31:$BO$33)) -> 99.8295 | AJ36: L | AN36: Σ V FD = | AR36: =+IF(OR(ISBLANK($X$33),ISBLANK($AN$31),ISBLANK($BD$31)),"",SUM($X$31:$AA$33,$AN$31:$AQ$33,$BD$31:$BG$33)) -> 100 | AZ36: L | BD36: MF = | BJ36: =IF(OR(ISBLANK($X$33),ISBLANK($AB$33),ISBLANK($AN$31),ISBLANK($AR$31),ISBLANK($BD$31),ISBLANK($BH$31)),"",$AB$36/$AR$36) -> 0.998295 | CA36: (digital)
B37: Justir | G37: (New KF = Old KF x MF ) , V/pulse | X37: Satuan | AD37: pulse/volume | AN37: Old KF | AT37: 99 | BD37: New KF | BJ37: =+IF(OR(ISBLANK($AD$37),ISBLANK($AT$37)),"",IF($AD$37="volume/pulse",$AT$37*$BJ$36,$AT$37/$BJ$36)) -> 99.169083 | CA37: =IF(OR(ABS($AJ$31)>0.5,ABS($AJ$32)>0.5,ABS($AJ$33)>0.5,ABS($AZ$31)>0.5,ABS($BP$31)>0.5,ABS($X$34)>0.5,ABS($AN$34)>0.5,ABS($BD$34)>0.5,$X$35>0.1),"BATAL","SAH") -> SAH
B38: K-Factor | G38: (New KF = Old KF / MF ) , pulse/V
B39: Akurasi Penjatah | X39: Penjatah Volume | AN39: Penjatah Harga | BD39: HASIL
X40: Kesalahan = | AE40: =IF(ISBLANK(X33),"",$X$34) -> 0.1225 | AK40: % | AN40: Kesalahan = | AU40: =IF(ISBLANK(AN31),"",$AN$34) -> 0.1925 | BA40: % | BD40: x | BH40: =IF(BD40="x","lolos","gagal") -> lolos | BL40: =+IF(BD40="x","-","x") -> - | BP40: =IF(BL40="x","lolos","gagal") -> gagal
B41: Anti-Drain , volume sisa dari nozle | X41: V = | AA41: 7 | AE41: mL | AI41: BKD | AL41: tanpa hose reel | AV41: = | AX41: =+IF(OR(ISBLANK(Data!$AU$20),ISBLANK(Cerapan!$AL$41)),"",IF(Cerapan!$AUL$1="tanpa hose reel",Data!$AU$20*0.01*1000,Data!$AU$20*0.02*1000)) -> 0 | BA41: mL | BD41: x | BH41: =IF(BD41="x","lolos","gagal") -> lolos | BL41: =+IF(BD41="x","-","x") -> - | BP41: =IF(BL41="x","lolos","gagal") -> gagal
B42: Laju Alir Maks. | X42: V = | AA42: 10 | AE42: L | AH42: t = | AK42: 10.5 | AO42: s | AR42: Q = | AU42: =+IF(OR(ISBLANK($AA$42),ISBLANK($AA$42)),"",$AA$42/$AK$42*60) -> 57.142857 | AZ42: L/min | BD42: x | BH42: =IF(BD42="x","lolos","gagal") -> lolos | BL42: =+IF(BD42="x","-","x") -> - | BP42: =IF(BL42="x","lolos","gagal") -> gagal
X43: Rasio laju alir (Q / Qmin) = | AR43: =IF(OR(ISBLANK($AA$42),ISBLANK($AK$42)),"",$AU$42/$AS$25) -> 8.7912088
...

Sheet Sheet1
